/*
* QUESTION
* There is a function suspiciousFunction, and for some reason you suspect that an exception might occur.
* Process the call of suspiciousFunction with the help of the try-catch-finally statement. If an exception occurs in the function, print an information message about it.
* In the case of IOException, print the following message instead: The IOException occurred.
* In the final block, output Handling completed successfully!.
*/

// SOLUTION CAN BE FOUND IN SOLUTION DIRECTORY

